package net.minecraft.world.gen.structure;

import net.minecraft.block.Block;
import net.minecraft.world.World;

import java.util.List;
import java.util.Random;

public class ComponentVillageHall extends ComponentVillage
{
    public ComponentVillageHall() {}

    public ComponentVillageHall(final ComponentVillageStartPiece par1ComponentVillageStartPiece, final int par2, final Random par3Random, final StructureBoundingBox par4StructureBoundingBox, final int par5)
    {
        super(par1ComponentVillageStartPiece, par2);
        this.coordBaseMode = par5;
        this.boundingBox = par4StructureBoundingBox;
    }

    public static ComponentVillageHall func_74906_a(final ComponentVillageStartPiece par0ComponentVillageStartPiece, final List par1List, final Random par2Random, final int par3, final int par4, final int par5, final int par6, final int par7)
    {
        final StructureBoundingBox structureboundingbox = StructureBoundingBox.getComponentToAddBoundingBox(par3, par4, par5, 0, 0, 0, 9, 7, 11, par6);
        return canVillageGoDeeper(structureboundingbox) && StructureComponent.findIntersecting(par1List, structureboundingbox) == null ? new ComponentVillageHall(par0ComponentVillageStartPiece, par7, par2Random, structureboundingbox, par6) : null;
    }

    /**
     * second Part of Structure generating, this for example places Spiderwebs, Mob Spawners, it closes Mineshafts at
     * the end, it adds Fences...
     */
    public boolean addComponentParts(final World par1World, final Random par2Random, final StructureBoundingBox par3StructureBoundingBox)
    {
        if (this.field_143015_k < 0)
        {
            this.field_143015_k = this.getAverageGroundLevel(par1World, par3StructureBoundingBox);

            if (this.field_143015_k < 0)
            {
                return true;
            }

            this.boundingBox.offset(0, this.field_143015_k - this.boundingBox.maxY + 7 - 1, 0);
        }

        this.fillWithBlocks(par1World, par3StructureBoundingBox, 1, 1, 1, 7, 4, 4, 0, 0, false);
        this.fillWithBlocks(par1World, par3StructureBoundingBox, 2, 1, 6, 8, 4, 10, 0, 0, false);
        this.fillWithBlocks(par1World, par3StructureBoundingBox, 2, 0, 6, 8, 0, 10, Block.dirt.blockID, Block.dirt.blockID, false);
        this.placeBlockAtCurrentPosition(par1World, Block.cobblestone.blockID, 0, 6, 0, 6, par3StructureBoundingBox);
        this.fillWithBlocks(par1World, par3StructureBoundingBox, 2, 1, 6, 2, 1, 10, Block.fence.blockID, Block.fence.blockID, false);
        this.fillWithBlocks(par1World, par3StructureBoundingBox, 8, 1, 6, 8, 1, 10, Block.fence.blockID, Block.fence.blockID, false);
        this.fillWithBlocks(par1World, par3StructureBoundingBox, 3, 1, 10, 7, 1, 10, Block.fence.blockID, Block.fence.blockID, false);
        this.fillWithBlocks(par1World, par3StructureBoundingBox, 1, 0, 1, 7, 0, 4, Block.planks.blockID, Block.planks.blockID, false);
        this.fillWithBlocks(par1World, par3StructureBoundingBox, 0, 0, 0, 0, 3, 5, Block.cobblestone.blockID, Block.cobblestone.blockID, false);
        this.fillWithBlocks(par1World, par3StructureBoundingBox, 8, 0, 0, 8, 3, 5, Block.cobblestone.blockID, Block.cobblestone.blockID, false);
        this.fillWithBlocks(par1World, par3StructureBoundingBox, 1, 0, 0, 7, 1, 0, Block.cobblestone.blockID, Block.cobblestone.blockID, false);
        this.fillWithBlocks(par1World, par3StructureBoundingBox, 1, 0, 5, 7, 1, 5, Block.cobblestone.blockID, Block.cobblestone.blockID, false);
        this.fillWithBlocks(par1World, par3StructureBoundingBox, 1, 2, 0, 7, 3, 0, Block.planks.blockID, Block.planks.blockID, false);
        this.fillWithBlocks(par1World, par3StructureBoundingBox, 1, 2, 5, 7, 3, 5, Block.planks.blockID, Block.planks.blockID, false);
        this.fillWithBlocks(par1World, par3StructureBoundingBox, 0, 4, 1, 8, 4, 1, Block.planks.blockID, Block.planks.blockID, false);
        this.fillWithBlocks(par1World, par3StructureBoundingBox, 0, 4, 4, 8, 4, 4, Block.planks.blockID, Block.planks.blockID, false);
        this.fillWithBlocks(par1World, par3StructureBoundingBox, 0, 5, 2, 8, 5, 3, Block.planks.blockID, Block.planks.blockID, false);
        this.placeBlockAtCurrentPosition(par1World, Block.planks.blockID, 0, 0, 4, 2, par3StructureBoundingBox);
        this.placeBlockAtCurrentPosition(par1World, Block.planks.blockID, 0, 0, 4, 3, par3StructureBoundingBox);
        this.placeBlockAtCurrentPosition(par1World, Block.planks.blockID, 0, 8, 4, 2, par3StructureBoundingBox);
        this.placeBlockAtCurrentPosition(par1World, Block.planks.blockID, 0, 8, 4, 3, par3StructureBoundingBox);
        final int i = this.getMetadataWithOffset(Block.stairsWoodOak.blockID, 3);
        final int j = this.getMetadataWithOffset(Block.stairsWoodOak.blockID, 2);
        int k;
        int l;

        for (k = -1; k <= 2; ++k)
        {
            for (l = 0; l <= 8; ++l)
            {
                this.placeBlockAtCurrentPosition(par1World, Block.stairsWoodOak.blockID, i, l, 4 + k, k, par3StructureBoundingBox);
                this.placeBlockAtCurrentPosition(par1World, Block.stairsWoodOak.blockID, j, l, 4 + k, 5 - k, par3StructureBoundingBox);
            }
        }

        this.placeBlockAtCurrentPosition(par1World, Block.wood.blockID, 0, 0, 2, 1, par3StructureBoundingBox);
        this.placeBlockAtCurrentPosition(par1World, Block.wood.blockID, 0, 0, 2, 4, par3StructureBoundingBox);
        this.placeBlockAtCurrentPosition(par1World, Block.wood.blockID, 0, 8, 2, 1, par3StructureBoundingBox);
        this.placeBlockAtCurrentPosition(par1World, Block.wood.blockID, 0, 8, 2, 4, par3StructureBoundingBox);
        this.placeBlockAtCurrentPosition(par1World, Block.thinGlass.blockID, 0, 0, 2, 2, par3StructureBoundingBox);
        this.placeBlockAtCurrentPosition(par1World, Block.thinGlass.blockID, 0, 0, 2, 3, par3StructureBoundingBox);
        this.placeBlockAtCurrentPosition(par1World, Block.thinGlass.blockID, 0, 8, 2, 2, par3StructureBoundingBox);
        this.placeBlockAtCurrentPosition(par1World, Block.thinGlass.blockID, 0, 8, 2, 3, par3StructureBoundingBox);
        this.placeBlockAtCurrentPosition(par1World, Block.thinGlass.blockID, 0, 2, 2, 5, par3StructureBoundingBox);
        this.placeBlockAtCurrentPosition(par1World, Block.thinGlass.blockID, 0, 3, 2, 5, par3StructureBoundingBox);
        this.placeBlockAtCurrentPosition(par1World, Block.thinGlass.blockID, 0, 5, 2, 0, par3StructureBoundingBox);
        this.placeBlockAtCurrentPosition(par1World, Block.thinGlass.blockID, 0, 6, 2, 5, par3StructureBoundingBox);
        this.placeBlockAtCurrentPosition(par1World, Block.fence.blockID, 0, 2, 1, 3, par3StructureBoundingBox);
        this.placeBlockAtCurrentPosition(par1World, Block.pressurePlatePlanks.blockID, 0, 2, 2, 3, par3StructureBoundingBox);
        this.placeBlockAtCurrentPosition(par1World, Block.planks.blockID, 0, 1, 1, 4, par3StructureBoundingBox);
        this.placeBlockAtCurrentPosition(par1World, Block.stairsWoodOak.blockID, this.getMetadataWithOffset(Block.stairsWoodOak.blockID, 3), 2, 1, 4, par3StructureBoundingBox);
        this.placeBlockAtCurrentPosition(par1World, Block.stairsWoodOak.blockID, this.getMetadataWithOffset(Block.stairsWoodOak.blockID, 1), 1, 1, 3, par3StructureBoundingBox);
        this.fillWithBlocks(par1World, par3StructureBoundingBox, 5, 0, 1, 7, 0, 3, Block.stoneDoubleSlab.blockID, Block.stoneDoubleSlab.blockID, false);
        this.placeBlockAtCurrentPosition(par1World, Block.stoneDoubleSlab.blockID, 0, 6, 1, 1, par3StructureBoundingBox);
        this.placeBlockAtCurrentPosition(par1World, Block.stoneDoubleSlab.blockID, 0, 6, 1, 2, par3StructureBoundingBox);
        this.placeBlockAtCurrentPosition(par1World, 0, 0, 2, 1, 0, par3StructureBoundingBox);
        this.placeBlockAtCurrentPosition(par1World, 0, 0, 2, 2, 0, par3StructureBoundingBox);
        this.placeBlockAtCurrentPosition(par1World, Block.torchWood.blockID, 0, 2, 3, 1, par3StructureBoundingBox);
        this.placeDoorAtCurrentPosition(par1World, par3StructureBoundingBox, par2Random, 2, 1, 0, this.getMetadataWithOffset(Block.doorWood.blockID, 1));

        if (this.getBlockIdAtCurrentPosition(par1World, 2, 0, -1, par3StructureBoundingBox) == 0 && this.getBlockIdAtCurrentPosition(par1World, 2, -1, -1, par3StructureBoundingBox) != 0)
        {
            this.placeBlockAtCurrentPosition(par1World, Block.stairsCobblestone.blockID, this.getMetadataWithOffset(Block.stairsCobblestone.blockID, 3), 2, 0, -1, par3StructureBoundingBox);
        }

        this.placeBlockAtCurrentPosition(par1World, 0, 0, 6, 1, 5, par3StructureBoundingBox);
        this.placeBlockAtCurrentPosition(par1World, 0, 0, 6, 2, 5, par3StructureBoundingBox);
        this.placeBlockAtCurrentPosition(par1World, Block.torchWood.blockID, 0, 6, 3, 4, par3StructureBoundingBox);
        this.placeDoorAtCurrentPosition(par1World, par3StructureBoundingBox, par2Random, 6, 1, 5, this.getMetadataWithOffset(Block.doorWood.blockID, 1));

        for (k = 0; k < 5; ++k)
        {
            for (l = 0; l < 9; ++l)
            {
                this.clearCurrentPositionBlocksUpwards(par1World, l, 7, k, par3StructureBoundingBox);
                this.fillCurrentPositionBlocksDownwards(par1World, Block.cobblestone.blockID, 0, l, -1, k, par3StructureBoundingBox);
            }
        }

        this.spawnVillagers(par1World, par3StructureBoundingBox, 4, 1, 2, 2);
        return true;
    }

    /**
     * Returns the villager type to spawn in this component, based on the number of villagers already spawned.
     */
    protected int getVillagerType(final int par1)
    {
        return par1 == 0 ? 4 : 0;
    }
}
